<?xml version="1.0"?>

<robot name="tripteron">
  
  <!-- *************************************************** -->
  <!-- ******************** Kinematics ******************* -->
  <!-- *************************************************** -->
  <!-- Note the 'origin' tag in the joints defines the
       shift and reorientation before the continuous joint
       rotates around the 'axis'. -->

  <link name="world"/>


  <joint name="rSlider" type="fixed">
    <parent link="world"/>
    <child  link="base_link"/>
  </joint>

  <link name="base_link">				<!-- Frame with the slider -->
    <visual>
      <origin xyz="0 0 0" rpy="0 0 0"/>	<!-- Center of slider -->
      <geometry>
	<box size="1 0.2 0.3" />	<!-- Size of horizontal slider -->
      </geometry>
      <material name="magenta"/>			<!-- Color -->
    </visual>
  </link>

  <!-- pulley controlling x & y pos -->
  <joint name="dist1" type="prismatic">
    <parent link="base_link"/>
    <child  link="base_1"/>
    <limit effort="1000.0" lower="0" upper="20.0" velocity="0.5"/>
    <origin xyz="-0.4 0 0.3" rpy="0 0 0"/>
    <axis   xyz="1 0 0"/>
  </joint>

  <link name="base_1">				<!-- Frame with cylinder -->
    <visual>
      <origin xyz="1 2 0.5" rpy="0 0 0"/>	<!-- Center of cylinder -->
      <geometry>
	<box size="0.2 .4 .1" />	<!-- Size of attachment point -->
      </geometry>
      <material name="cyan"/>			<!-- Color -->
    </visual>
  </link>

  


  <!-- *************************************************** -->
  <!-- ********************* Graphics ******************** -->
  <!-- *************************************************** -->
  <!-- The following is purely to make this look roboticy. -->
  <!-- The 'origin' tag in the link/visual defines the
       center of the object (box, cylinder, sphere, mesh)
       but does not affect the joint chain kinematics. -->

  <!-- *************** Materials / Colors **************** -->

  <material name="white">    <color rgba="1.00 1.00 1.00 1"/>  </material>
  <material name="gray">     <color rgba="0.60 0.60 0.60 1"/>  </material>
  <material name="table">    <color rgba="0.85 0.77 0.77 1"/>  </material>
  <material name="black">    <color rgba="0.00 0.00 0.00 1"/>  </material>

  <material name="red">      <color rgba="1.00 0.00 0.00 1"/>  </material>
  <material name="green">    <color rgba="0.00 1.00 0.00 1"/>  </material>
  <material name="blue">     <color rgba="0.00 0.00 1.00 1"/>  </material>

  <material name="cyan">     <color rgba="0.00 1.00 1.00 1"/>  </material>
  <material name="magenta">  <color rgba="1.00 0.00 1.00 1"/>  </material>
  <material name="yellow">   <color rgba="1.00 1.00 0.00 1"/>  </material>

  <material name="orange">   <color rgba="1.00 0.65 0.00 1"/>  </material>


 </robot>

